<?xml version="1.0" ?>
<robot name="skid4wd" xmlns:xacro="http://www.ros.org/wiki/xacro">

<xacro:include filename="$(find skid4wd_description)/urdf/materials.xacro" />
<xacro:include filename="$(find skid4wd_description)/urdf/skid4wd.trans" />
<xacro:include filename="$(find skid4wd_description)/urdf/skid4wd.gazebo" />
<xacro:include filename="$(find skid4wd_description)/urdf/stereo_camera2.urdf.xacro" />


<xacro:property name="PI" value="3.14"/>
<xacro:property name="PI_half" value="1.5708"/>
<xacro:property name="PI_2" value="1.5708"/>
<xacro:property name="PI_4" value="0.7854"/>
<xacro:property name="mPI_4" value="-0.7854"/>
<xacro:property name="PI_3_4" value="2.3562"/>
<xacro:property name="mPI_3_4" value="-2.3562"/>
<xacro:property name="PI_12" value="0.2618"/>
<xacro:property name="mPI_12" value="-0.2618"/>
<xacro:property name="PI_6" value="0.5236"/>
<xacro:property name="mPI_6" value="-0.5236"/>
<xacro:property name="PI_5_12" value="1.3090"/>
<xacro:property name="mPI_5_12" value="-1.3090"/>

<!-- SENSORS -->

<!--ULTRASONIC SENSORS (front (right , left) and rear (right, left) and rear and front_mid(left,right)-->
<joint name="sonar_front_right_joint" type="fixed">
    <axis xyz="0 1 0" />
    <origin rpy="0 ${mPI_12} ${mPI_4}" xyz="0.58 -0.29 0.16" /> <!--z raised from 5 to 16 bcs of bodywork raise
                                                                      same with all sonar joints-->
    <parent link="base_link"/>
    <child link="base_sonar_front_right"/>
</joint><link name="base_sonar_front_right">
    <collision>
      <origin xyz="0 0 0" rpy="0 0 0"/>
      <geometry>
        <box size="0.01 0.01 0.01"/>
      </geometry>
    </collision>    <visual>
      <origin xyz="0 0 0" rpy="0 0 0"/>
      <geometry>
        <box size="0.01 0.01 0.01"/>
      </geometry>
    </visual>    <inertial>
      <mass value="1e-5" />
      <origin xyz="0 0 0" rpy="0 0 0"/>
      <inertia ixx="1e-6" ixy="0" ixz="0" iyy="1e-6" iyz="0" izz="1e-6" />
    </inertial>
 </link>

 <joint name="sonar_front_left_joint" type="fixed">
    <axis xyz="0 1 0" />
    <origin rpy="0 ${mPI_12} ${PI_4}" xyz="0.58 +0.29 0.16" />
    <parent link="base_link"/>
    <child link="base_sonar_front_left"/>
</joint><link name="base_sonar_front_left">
    <collision>
      <origin xyz="0 0 0" rpy="0 0 0"/>
      <geometry>
        <box size="0.01 0.01 0.01"/>
      </geometry>
    </collision>    <visual>
      <origin xyz="0 0 0" rpy="0 0 0"/>
      <geometry>
        <box size="0.01 0.01 0.01"/>
      </geometry>
    </visual>    <inertial>
      <mass value="1e-5" />
      <origin xyz="0 0 0" rpy="0 0 0"/>
      <inertia ixx="1e-6" ixy="0" ixz="0" iyy="1e-6" iyz="0" izz="1e-6" />
    </inertial>
 </link>

<joint name="sonar_front_mid_right_joint" type="fixed">
    <axis xyz="0 1 0" />
    <origin rpy="0 ${mPI_12} 0" xyz="0.62 -0.14 0.16" />
    <parent link="base_link"/>
    <child link="base_sonar_front_mid_right"/>
</joint><link name="base_sonar_front_mid_right">
    <collision>
      <origin xyz="0 0 0" rpy="0 0 0"/>
      <geometry>
        <box size="0.01 0.01 0.01"/>
      </geometry>
    </collision>    <visual>
      <origin xyz="0 0 0" rpy="0 0 0"/>
      <geometry>
        <box size="0.01 0.01 0.01"/>
      </geometry>
    </visual>    <inertial>
      <mass value="1e-5" />
      <origin xyz="0 0 0" rpy="0 0 0"/>
      <inertia ixx="1e-6" ixy="0" ixz="0" iyy="1e-6" iyz="0" izz="1e-6" />
    </inertial>
 </link>

 <joint name="sonar_front_mid_left_joint" type="fixed">
    <axis xyz="0 1 0" />
    <origin rpy="0 ${mPI_12} 0" xyz="0.62 +0.14 0.16" />
    <parent link="base_link"/>
    <child link="base_sonar_front_mid_left"/>
</joint><link name="base_sonar_front_mid_left">
    <collision>
      <origin xyz="0 0 0" rpy="0 0 0"/>
      <geometry>
        <box size="0.01 0.01 0.01"/>
      </geometry>
    </collision>    <visual>
      <origin xyz="0 0 0" rpy="0 0 0"/>
      <geometry>
        <box size="0.01 0.01 0.01"/>
      </geometry>
    </visual>    <inertial>
      <mass value="1e-5" />
      <origin xyz="0 0 0" rpy="0 0 0"/>
      <inertia ixx="1e-6" ixy="0" ixz="0" iyy="1e-6" iyz="0" izz="1e-6" />
    </inertial>
 </link>

 <joint name="sonar_rear_right_joint" type="fixed">
    <axis xyz="0 1 0" />
    <origin rpy="0 0 ${mPI_3_4}" xyz="-0.59 -0.28 0.30" />
    <parent link="base_link"/>
    <child link="base_sonar_rear_right"/>
</joint><link name="base_sonar_rear_right">
    <collision>
      <origin xyz="0 0 0" rpy="0 0 0"/>
      <geometry>
        <box size="0.01 0.01 0.01"/>
      </geometry>
    </collision>    <visual>
      <origin xyz="0 0 0" rpy="0 0 0"/>
      <geometry>
        <box size="0.01 0.01 0.01"/>
      </geometry>
    </visual>    <inertial>
      <mass value="1e-5" />
      <origin xyz="0 0 0" rpy="0 0 0"/>
      <inertia ixx="1e-6" ixy="0" ixz="0" iyy="1e-6" iyz="0" izz="1e-6" />
    </inertial>
 </link>

 <joint name="sonar_rear_joint" type="fixed">
    <axis xyz="0 1 0" />
    <origin rpy="0 0 ${PI}" xyz="-0.63 0 0.30" />
    <parent link="base_link"/>
    <child link="base_sonar_rear"/>
</joint><link name="base_sonar_rear">
    <collision>
      <origin xyz="0 0 0" rpy="0 0 0"/>
      <geometry>
        <box size="0.01 0.01 0.01"/>
      </geometry>
    </collision>    <visual>
      <origin xyz="0 0 0" rpy="0 0 0"/>
      <geometry>
        <box size="0.01 0.01 0.01"/>
      </geometry>
    </visual>    <inertial>
      <mass value="1e-5" />
      <origin xyz="0 0 0" rpy="0 0 0"/>
      <inertia ixx="1e-6" ixy="0" ixz="0" iyy="1e-6" iyz="0" izz="1e-6" />
    </inertial>
 </link>

 <joint name="sonar_rear_left_joint" type="fixed">
    <axis xyz="0 1 0" />
    <origin rpy="0 0 ${PI_3_4}" xyz="-0.59 +0.28 0.30" />
    <parent link="base_link"/>
    <child link="base_sonar_rear_left"/>
</joint><link name="base_sonar_rear_left">
    <collision>
      <origin xyz="0 0 0" rpy="0 0 0"/>
      <geometry>
        <box size="0.01 0.01 0.01"/>
      </geometry>
    </collision>    <visual>
      <origin xyz="0 0 0" rpy="0 0 0"/>
      <geometry>
        <box size="0.01 0.01 0.01"/>
      </geometry>
    </visual>    <inertial>
      <mass value="1e-5" />
      <origin xyz="0 0 0" rpy="0 0 0"/>
      <inertia ixx="1e-6" ixy="0" ixz="0" iyy="1e-6" iyz="0" izz="1e-6" />
    </inertial>
 </link>

 <gazebo reference="base_sonar_front_right">        
   <sensor type="ray" name="TeraRanger_fr">
      <pose>0 0 0 0 0 0</pose>
      <visualize>true</visualize>
      <update_rate>50</update_rate>
      <ray>
         <scan>
            <horizontal>
               <samples>10</samples>
               <resolution>1</resolution> 
               <min_angle>${mPI_12}</min_angle>
               <max_angle>${PI_12}</max_angle>
            </horizontal>
            <vertical>
               <samples>10</samples>
               <resolution>1</resolution> 
               <min_angle>${mPI_12}</min_angle>
               <max_angle>${PI_12}</max_angle>
            </vertical>
         </scan>
         <range>
            <min>0.01</min>
            <max>0.4</max>
            <resolution>0.02</resolution>
         </range>
      </ray>
      <plugin filename="libgazebo_ros_range.so" name="gazebo_ros_range">
         <gaussianNoise>0.005</gaussianNoise>
         <alwaysOn>true</alwaysOn>
         <updateRate>50</updateRate>
         <topicName>sensor_msgs/sonar_front_right</topicName>
         <frameName>base_sonar_front_right</frameName>
         <radiation>ULTRASOUND</radiation>
         <fov>0.2967</fov>
      </plugin>
   </sensor>  
   </gazebo>

   <gazebo reference="base_sonar_front_left">        
   <sensor type="ray" name="TeraRanger_fl">
      <pose>0 0 0 0 0 0</pose>
      <visualize>true</visualize>
      <update_rate>50</update_rate>
      <ray>
         <scan>
            <horizontal>
               <samples>10</samples>
               <resolution>1</resolution> 
               <min_angle>${mPI_12}</min_angle>
               <max_angle>${PI_12}</max_angle>
            </horizontal>
            <vertical>
               <samples>10</samples>
               <resolution>1</resolution> 
              <min_angle>${mPI_12}</min_angle>
               <max_angle>${PI_12}</max_angle>
            </vertical>
         </scan>
         <range>
            <min>0.01</min>
            <max>0.4</max>
            <resolution>0.02</resolution>
         </range>
      </ray>
      <plugin filename="libgazebo_ros_range.so" name="gazebo_ros_range">
         <gaussianNoise>0.005</gaussianNoise>
         <alwaysOn>true</alwaysOn>
         <updateRate>50</updateRate>
         <topicName>sensor_msgs/sonar_front_left</topicName>
         <frameName>base_sonar_front_left</frameName>
         <radiation>ULTRASOUND</radiation>
         <fov>0.2967</fov>
      </plugin>
   </sensor>  
   </gazebo>
   
   <gazebo reference="base_sonar_front_mid_right">        
   <sensor type="ray" name="TeraRanger_fmr">
      <pose>0 0 0 0 0 0</pose>
      <visualize>true</visualize>
      <update_rate>50</update_rate>
      <ray>
         <scan>
            <horizontal>
               <samples>10</samples>
               <resolution>1</resolution> 
               <min_angle>${mPI_12}</min_angle>
               <max_angle>${PI_12}</max_angle>
            </horizontal>
            <vertical>
               <samples>10</samples>
               <resolution>1</resolution> 
               <min_angle>${mPI_12}</min_angle>
               <max_angle>${PI_12}</max_angle>
            </vertical>
         </scan>
         <range>
            <min>0.01</min>
            <max>0.4</max>
            <resolution>0.02</resolution>
         </range>
      </ray>
      <plugin filename="libgazebo_ros_range.so" name="gazebo_ros_range">
         <gaussianNoise>0.005</gaussianNoise>
         <alwaysOn>true</alwaysOn>
         <updateRate>50</updateRate>
         <topicName>sensor_msgs/sonar_front_mid_right</topicName>
         <frameName>base_sonar_front_mid_right</frameName>
         <radiation>ULTRASOUND</radiation>
         <fov>0.2967</fov>
      </plugin>
   </sensor>  
   </gazebo>

   <gazebo reference="base_sonar_front_mid_left">        
   <sensor type="ray" name="TeraRanger_fml">
      <pose>0 0 0 0 0 0</pose>
      <visualize>true</visualize>
      <update_rate>50</update_rate>
      <ray>
         <scan>
            <horizontal>
               <samples>10</samples>
               <resolution>1</resolution> 
               <min_angle>${mPI_12}</min_angle>
               <max_angle>${PI_12}</max_angle>
            </horizontal>
            <vertical>
               <samples>10</samples>
               <resolution>1</resolution> 
              <min_angle>${mPI_12}</min_angle>
               <max_angle>${PI_12}</max_angle>
            </vertical>
         </scan>
         <range>
            <min>0.01</min>
            <max>0.4</max>
            <resolution>0.02</resolution>
         </range>
      </ray>
      <plugin filename="libgazebo_ros_range.so" name="gazebo_ros_range">
         <gaussianNoise>0.005</gaussianNoise>
         <alwaysOn>true</alwaysOn>
         <updateRate>50</updateRate>
         <topicName>sensor_msgs/sonar_front_mid_left</topicName>
         <frameName>base_sonar_front_mid_left</frameName>
         <radiation>ULTRASOUND</radiation>
         <fov>0.2967</fov>
      </plugin>
   </sensor>  
   </gazebo>

   <gazebo reference="base_sonar_rear_right">        
   <sensor type="ray" name="TeraRanger_rr">
      <pose>0 0 0 0 0 0</pose>
      <visualize>true</visualize>
      <update_rate>50</update_rate>
      <ray>
         <scan>
            <horizontal>
               <samples>10</samples>
               <resolution>1</resolution> 
              <min_angle>${mPI_12}</min_angle>
               <max_angle>${PI_12}</max_angle>
            </horizontal>
            <vertical>
               <samples>10</samples>
               <resolution>1</resolution> 
              <min_angle>${mPI_12}</min_angle>
               <max_angle>${PI_12}</max_angle>
            </vertical>
         </scan>
         <range>
            <min>0.01</min>
            <max>0.4</max>
            <resolution>0.02</resolution>
         </range>
      </ray>
      <plugin filename="libgazebo_ros_range.so" name="gazebo_ros_range">
         <gaussianNoise>0.005</gaussianNoise>
         <alwaysOn>true</alwaysOn>
         <updateRate>50</updateRate>
         <topicName>sensor_msgs/sonar_rear_right</topicName>
         <frameName>base_sonar_rear_right</frameName>
         <radiation>ULTRASOUND</radiation>
         <fov>0.2967</fov>
      </plugin>
   </sensor>  
   </gazebo>

   <gazebo reference="base_sonar_rear_left">        
   <sensor type="ray" name="TeraRanger_rl">
      <pose>0 0 0 0 0 0</pose>
      <visualize>true</visualize>
      <update_rate>50</update_rate>
      <ray>
         <scan>
            <horizontal>
               <samples>10</samples>
               <resolution>1</resolution> 
              <min_angle>${mPI_12}</min_angle>
               <max_angle>${PI_12}</max_angle>
            </horizontal>
            <vertical>
               <samples>10</samples>
               <resolution>1</resolution> 
               <min_angle>${mPI_12}</min_angle>
               <max_angle>${PI_12}</max_angle>
            </vertical>
         </scan>
         <range>
            <min>0.01</min>
            <max>0.4</max>
            <resolution>0.02</resolution>
         </range>
      </ray>
      <plugin filename="libgazebo_ros_range.so" name="gazebo_ros_range">
         <gaussianNoise>0.005</gaussianNoise>
         <alwaysOn>true</alwaysOn>
         <updateRate>50</updateRate>
         <topicName>sensor_msgs/sonar_rear_left</topicName>
         <frameName>base_sonar_rear_left</frameName>
         <radiation>ULTRASOUND</radiation>
         <fov>0.2967</fov>
      </plugin>
   </sensor>  
   </gazebo>
   
   <gazebo reference="base_sonar_rear">        
   <sensor type="ray" name="TeraRanger_rrr">
      <pose>0 0 0 0 0 0</pose>
      <visualize>true</visualize>
      <update_rate>50</update_rate>
      <ray>
         <scan>
            <horizontal>
               <samples>10</samples>
               <resolution>1</resolution> 
              <min_angle>${mPI_12}</min_angle>
               <max_angle>${PI_12}</max_angle>
            </horizontal>
            <vertical>
               <samples>10</samples>
               <resolution>1</resolution> 
              <min_angle>${mPI_12}</min_angle>
               <max_angle>${PI_12}</max_angle>
            </vertical>
         </scan>
         <range>
            <min>0.01</min>
            <max>0.4</max>
            <resolution>0.02</resolution>
         </range>
      </ray>
      <plugin filename="libgazebo_ros_range.so" name="gazebo_ros_range">
         <gaussianNoise>0.005</gaussianNoise>
         <alwaysOn>true</alwaysOn>
         <updateRate>50</updateRate>
         <topicName>sensor_msgs/sonar_rear</topicName>
         <frameName>base_sonar_rear</frameName>
         <radiation>ULTRASOUND</radiation>
         <fov>0.2967</fov>
      </plugin>
   </sensor>  
   </gazebo>

   <!-- IMU sensor -->

  <joint name="imu_joint" type="fixed">
    <axis xyz="1 0 0"/> <!-- 0 1 0 -->
    <origin xyz="0 0 0.30"/>
    <parent link="base_link"/>
    <child link="imu_link"/>
  </joint>


  <link name="imu_link">
    <inertial>
      <mass value="0.001"/>
      <origin rpy="0 0 0" xyz="0 0 0"/>
      <inertia ixx="0.0001" ixy="0" ixz="0" iyy="0.000001" iyz="0" izz="0.0001"/>
    </inertial>
    <visual>
      <origin rpy="0 0 0" xyz="0 0 0"/>
      <geometry>
        <box size="0.01 0.01 0.01"/>
      </geometry>
    </visual>
    <collision>
      <origin rpy="0 0 0" xyz="0 0 0"/>
      <geometry>
        <box size=".001 .001 .001"/>
      </geometry>
    </collision>
  </link>

  <gazebo reference="imu_link">
    <gravity>true</gravity>
    <sensor name="imu_sensor" type="imu">
      <always_on>true</always_on>
      <update_rate>100</update_rate>
      <visualize>true</visualize>
      <topic>__default_topic__</topic>
      <plugin filename="libgazebo_ros_imu_sensor.so" name="imu_plugin">
        <topicName>sensor_msgs/imu</topicName>
        <bodyName>imu_link</bodyName>
        <updateRateHZ>10.0</updateRateHZ>
        <gaussianNoise>0.2</gaussianNoise>
        <xyzOffset>0 0 0</xyzOffset>
        <rpyOffset>0 0 0</rpyOffset>
        <frameName>imu_link</frameName>
        <initialOrientationAsReference>false</initialOrientationAsReference>
      </plugin>
      <pose>0 0 0 0 0 0</pose>
    </sensor>
  </gazebo>

<!-- LINKS -->
<!-- Building the robot frame, wheels etc...-->
<link name="base_link">
  <inertial>
    <origin rpy="${PI_2} 0 ${PI_2}" xyz="-0.010646286022740195 -4.919653835224294e-16 0.07524542881356616"/>
    <mass value="47.91821428809842"/>
    <inertia ixx="1.403392" ixy="0.0" ixz="0.109412" iyy="4.035328" iyz="-0.0" izz="4.747708"/>
  </inertial>
  <fdir1 value="1 0 0"/>
  <visual>
    <origin rpy="0 0 0" xyz="0 0 0.1"/> <!-- Rised bodywork fo r10 cm TODO: DEBUG ...-->
    <geometry>
      <mesh filename="package://skid4wd_description/meshes/base_link.stl" scale="0.025 0.025 0.025"/>
    </geometry>
    <material name="orange"/>
  </visual>
  <collision>
    <origin rpy="0 0 0" xyz="0 0 0.1"/>
    <geometry>
		
      <mesh filename="package://skid4wd_description/meshes/base_link.stl" scale="0.025 0.025 0.025"/>
	  <!--mesh has spikes fo rwheels
      <box size="0.6 0.3 0.3" />...-->
    </geometry>
  </collision>
</link>


<link name="wheel_front_left_1">
  <inertial>
    <origin rpy="0 0 0" xyz="2.3943220794908626e-08 -0.019939147977344326 -1.8492763799449197e-08"/>
    <mass value="0.552895033700559"/>
    <inertia ixx="0.04984" ixy="0.0" ixz="-0.0" iyy="0.008384" iyz="-0.0" izz="0.004984"/>
  </inertial>
  <visual>
    <origin rpy="0 0 0" xyz="-0.02 0.010 -0.025"/>
    <geometry>
      <mesh filename="package://skid4wd_description/meshes/wheel.dae" scale="2 2 2"/>
    </geometry>
    <material name="silver"/>
  </visual>
  <collision>
    <origin rpy="${PI/2} 0 0" xyz="0 0 0"/>
    <geometry>
      <cylinder length="0.1" radius="0.16"/>
    </geometry>
  </collision>
</link>

<link name="wheel_front_right_1">
  <inertial>
    <origin rpy="0 0 0" xyz="1.796076479210207e-08 0.019939147977344354 1.3632938049290555e-08"/>
    <mass value="0.552895033700559"/>
    <inertia ixx="0.04984" ixy="0.0" ixz="-0.0" iyy="0.008384" iyz="-0.0" izz="0.004984"/>
  </inertial>
  <visual>
    <origin rpy="0 0 ${PI}" xyz="0.02 -0.010 -0.025"/>
    <geometry>
      <mesh filename="package://skid4wd_description/meshes/wheel.dae" scale="2 2 2"/>
    </geometry>
    <material name="silver"/>
  </visual>
  <collision>
    <origin rpy="${PI/2} 0 0" xyz="0 0 0"/>
    <geometry>
      <cylinder length="0.1" radius="0.16"/>
    </geometry>
  </collision>
</link>

<link name="wheel_rear_left_1">
  <inertial>
    <origin rpy="0 0 0" xyz="2.481888500271978e-08 -0.019939147977344326 -1.6256707337930498e-08"/>
	<mass value="0.552895033700559"/>
    <inertia ixx="0.04984" ixy="0.0" ixz="-0.0" iyy="0.008384" iyz="-0.0" izz="0.004984"/>
  </inertial>
  <visual>
    <origin rpy="0 0 0" xyz="-0.02 0.010 -0.025"/>
    <geometry>
      <mesh filename="package://skid4wd_description/meshes/wheel.dae" scale="2 2 2"/>
    </geometry>
    <material name="silver"/>
  </visual>
  <collision>
    <origin rpy="${PI/2} 0 0" xyz="0 0 0"/>
    <geometry>
      <cylinder length="0.1" radius="0.16"/>
    </geometry>
  </collision>
</link>

<link name="wheel_rear_right_1">
  <inertial>
    <origin rpy="0 0 0" xyz="2.1544820399954645e-08 0.01993914797734427 1.3912224119255745e-08"/>
    <mass value="0.552895033700559"/>
    <inertia ixx="0.04984" ixy="0.0" ixz="-0.0" iyy="0.008384" iyz="-0.0" izz="0.004984"/>
  </inertial>
  <visual>
    <origin rpy="0 0 ${PI}" xyz="0.02 -0.010 -0.025"/>
    <geometry>
      <mesh filename="package://skid4wd_description/meshes/wheel.dae" scale="2 2 2"/>
    </geometry>
    <material name="silver"/>
  </visual>
  <collision>
    <origin rpy="${PI/2} 0 0" xyz="0 0 0"/>
    <geometry>
      <cylinder length="0.1" radius="0.16"/>
    </geometry>
  </collision>
</link>

<!-- 
  Adding robotic hand
  -->
<link name="riser">
  <inertial>
    <origin rpy="0 0 0" xyz="0.0 0.0 0.0"/>
    <mass value="2"/>
    <inertia ixx="0.01" ixy="0.0" ixz="0.0" iyy="0.01" iyz="0.0" izz="0.01"/>
  </inertial>
  <visual>
    <origin rpy="0.0 0.0 0.0" xyz="0.50 0 0.4"/>
    <geometry>
      <box size="0.1 0.1 0.8" />
    </geometry>
    <material name="orange"/>
  </visual>
  <collision>
    <origin rpy="0.0 0.0 0.0" xyz="0.50 0 0.4"/>
    <geometry>
      <box size="0.1 0.1 0.8" />
    </geometry>
</collision>
</link>

<link name="palm">
  <inertial>
    <origin rpy="0 0 0" xyz="0.0 0.0 0.0"/>
    <mass value="0.05"/>
    <inertia ixx="0.01" ixy="0.0" ixz="0.0" iyy="0.01" iyz="0.0" izz="0.01"/>
  </inertial>
  <visual>
    <origin rpy="0 0 0" xyz="0.56 0 0.10"/>
    <geometry>
      <box size="0.04 0.04 0.08" />
    </geometry>
    <material name="orange"/>
  </visual>
  <collision>
    <origin rpy="0 0 0" xyz="0.56 0 0.10"/>
    <geometry>
      <box size="0.04 0.04 0.08" />
    </geometry>
  </collision>
</link>

<!-- Camera mount link-->

<link name="camera_mount">
  <visual>
    <geometry>
      <cylinder radius="0.04" length="0.2" />
    </geometry>
    <material name="">
    </material>
  </visual>
</link>
<gazebo reference="camera_mount">
  <material>Gazebo/Blue</material>
</gazebo>
<joint name="camera_mount_joint" type="fixed">
  <parent link="base_link" />
  <child link="camera_mount" />
  <origin xyz="0.5 0.0 0.8" rpy="0 0 0" />
</joint>

<!-- camera -->
<xacro:stereo_camera parent="camera_mount" origin="0 0 0.12" /> 


<!-- camera INTEL
<xacro:include filename="$(find skid4wd_description)/urdf/_d435.urdf.xacro" />
<sensor_d435 parent="camera_mount">
</sensor_d435>
-->
   
<!-- 
  JOINTS
-->

<!-- Fixed hand joint -->
<joint name="joint_hand_fix" type="fixed">
  <parent link="base_link"/>
  <child link="riser"/>
</joint>

<joint name="joint_palm_riser" type="prismatic">
  <parent link="riser"/>
  <child link="palm"/>
  <origin xyz="0.0 0.0 0.0" rpy="0.0 0.0 0.0"/>
  <axis xyz="0 0 1"/>
  <limit effort="10.0" lower="0.0" upper="0.35" velocity="0.5"/>
</joint>

<joint name="joint_front_left" type="continuous"> 
  <origin rpy="0 0 0" xyz="0.30 0.38 -0.04"/>
  <parent link="base_link"/>
  <child link="wheel_front_left_1"/>
  <axis xyz="0.0 1.0 0.0"/>
  <limit effort="2000" velocity="10"/>
  <joint_properties damping="20000.0" friction="2.0"/>
  <cfm>0.0017</cfm> 
  <erp>0.17</erp>
</joint>

<joint name="joint_front_right" type="continuous">
  <origin rpy="0 0 0" xyz="0.30 -0.38 -0.04"/>
  <parent link="base_link"/>
  <child link="wheel_front_right_1"/>
  <axis xyz="0.0 1.0 0.0"/>
  <limit effort="2000" velocity="10"/>
  <joint_properties damping="20000.0" friction="2.0"/>
  <cfm>0.000017</cfm> 
  <erp>0.17</erp>
</joint>

<joint name="joint_rear_left" type="continuous">
  <origin rpy="0 0 0" xyz="-0.320 0.38 -0.04"/>
  <parent link="base_link"/>
  <child link="wheel_rear_left_1"/>
  <axis xyz="0.0 1.0 0.0"/>
  <limit effort="2000" velocity="10"/>
  <joint_properties damping="20000.0" friction="2.0"/>
  <cfm>0.000017</cfm> 
  <erp>0.17</erp>
</joint>

<joint name="joint_rear_right" type="continuous">
  <origin rpy="0 0 0" xyz="-0.320 -0.38 -0.04"/>
  <parent link="base_link"/>
  <child link="wheel_rear_right_1"/>
  <axis xyz="0.0 1.0 0.0"/>
  <limit effort="2000" velocity="10"/>
  <joint_properties damping="20000.0" friction="2.0"/>
  <cfm>0.000017</cfm> 
  <erp>0.17</erp>
</joint>

</robot>
